Workbook

Sheet Actual Expenses
B2: Start Date | C2: 45536
B4: Actual Operating Expenses
B5: Account # | C5: Department | D5: Description | E5: =$C$2 -> 45536 | F5: =+EDATE(E$5,1) -> 45566 | G5: =+EDATE(F$5,1) -> 45597 | H5: =+EDATE(G$5,1) -> 45627
B6: 11256 | C6: Marketing | D6: Paid Ads | E6: 22992 | F6: 24001 | G6: 26558 | H6: 25446
B7: 11257 | C7: Marketing | D7: Infuencers | E7: 53326 | F7: 54223 | G7: 51000 | H7: 50000
B8: 11259 | C8: Engineering | D8: Consulting | E8: 35888 | F8: 36880 | G8: 37995 | H8: 40000
B9: 11260 | C9: Engineering | D9: Travel | E9: 87942 | F9: 85224 | G9: 82469 | H9: 81005
B10: 11263 | C10: Support | D10: Software | E10: 92622 | F10: 90005 | G10: 87556 | H10: 84522
B11: 11264 | C11: Support | D11: Call Center | E11: 27416 | F11: 26554 | G11: 24330 | H11: 22338
B12: 11267 | C12: HR | D12: Recruiting Events | E12: 41696 | F12: 41696 | G12: 42558 | H12: 45448
B13: 11268 | C13: HR | D13: Meetups | E13: 60285 | F13: 61225 | G13: 68994 | H13: 72410

Sheet Forecast
D2: best | E2: 0.3
D3: worst | E3: 0.3
B8: 1. | E8: Actuals | I8: Forecast
A9: x | B9: Account # | C9: Department | D9: Description | E9: ='Actual Expenses'!$C$2 -> 45536 | F9: =+EDATE(E$21,1) -> 45566 | G9: =+EDATE(F$21,1) -> 45597 | H9: =+EDATE(G$21,1) -> 45627 | I9: =+EDATE(H$21,1) -> 45658 | J9: =+EDATE(I$21,1) -> 45689 | K9: =+EDATE(J$21,1) -> 45717 | L9: =+EDATE(K$21,1) -> 45748 | M9: =+EDATE(L$21,1) -> 45778 | ... T9: =+EDATE(S$21,1) -> 45992
B10: 11256 | C10: Marketing | D10: Paid Ads | E10: 22992 | F10: 24001 | G10: 26558 | H10: 25446 | I10: =+CHOOSE('Income Statement'!$C$2,Forecast!I22,Forecast!I35,Forecast!I46) -> 314259.21 | J10: =+CHOOSE('Income Statement'!$C$2,Forecast!J22,Forecast!J35,Forecast!J46) -> 314994.34 | K10: =+CHOOSE('Income Statement'!$C$2,Forecast!K22,Forecast!K35,Forecast!K46) -> 334154.57 | L10: =+CHOOSE('Income Statement'!$C$2,Forecast!L22,Forecast!L35,Forecast!L46) -> 333466.75 | M10: =+CHOOSE('Income Statement'!$C$2,Forecast!M22,Forecast!M35,Forecast!M46) -> 352185.76 | N10: =+CHOOSE('Income Statement'!$C$2,Forecast!N22,Forecast!N35,Forecast!N46) -> 352307.11 | O10: =+CHOOSE('Income Statement'!$C$2,Forecast!O22,Forecast!O35,Forecast!O46) -> 370564.62 | P10: =+CHOOSE('Income Statement'!$C$2,Forecast!P22,Forecast!P35,Forecast!P46) -> 370696.23 | ... T10: =+CHOOSE('Income Statement'!$C$2,Forecast!T22,Forecast!T35,Forecast!T46) -> 407357.38
B11: 11257 | C11: Marketing | D11: Infuencers | E11: 53326 | F11: 54223 | G11: 51000 | H11: 50000 | I11: =+CHOOSE('Income Statement'!$C$2,Forecast!I23,Forecast!I36,Forecast!I47) -> 571644.96 | J11: =+CHOOSE('Income Statement'!$C$2,Forecast!J23,Forecast!J36,Forecast!J47) -> 556755.81 | K11: =+CHOOSE('Income Statement'!$C$2,Forecast!K23,Forecast!K36,Forecast!K47) -> 536375.04 | L11: =+CHOOSE('Income Statement'!$C$2,Forecast!L23,Forecast!L36,Forecast!L47) -> 521719.27 | M11: =+CHOOSE('Income Statement'!$C$2,Forecast!M23,Forecast!M36,Forecast!M47) -> 501598.36 | N11: =+CHOOSE('Income Statement'!$C$2,Forecast!N23,Forecast!N36,Forecast!N47) -> 487416.09 | O11: =+CHOOSE('Income Statement'!$C$2,Forecast!O23,Forecast!O36,Forecast!O47) -> 464504.02 | P11: =+CHOOSE('Income Statement'!$C$2,Forecast!P23,Forecast!P36,Forecast!P47) -> 450769.14 | ... T11: =+CHOOSE('Income Statement'!$C$2,Forecast!T23,Forecast!T36,Forecast!T47) -> 378135.41
B12: 11259 | C12: Engineering | D12: Consulting | E12: 35888 | F12: 36880 | G12: 37995 | H12: 40000 | I12: =+CHOOSE('Income Statement'!$C$2,Forecast!I24,Forecast!I37,Forecast!I48) -> 481852.46 | J12: =+CHOOSE('Income Statement'!$C$2,Forecast!J24,Forecast!J37,Forecast!J48) -> 498579.96 | K12: =+CHOOSE('Income Statement'!$C$2,Forecast!K24,Forecast!K37,Forecast!K48) -> 515223.16 | L12: =+CHOOSE('Income Statement'!$C$2,Forecast!L24,Forecast!L37,Forecast!L48) -> 531342.77 | M12: =+CHOOSE('Income Statement'!$C$2,Forecast!M24,Forecast!M37,Forecast!M48) -> 547730.44 | N12: =+CHOOSE('Income Statement'!$C$2,Forecast!N24,Forecast!N37,Forecast!N48) -> 564119.14 | O12: =+CHOOSE('Income Statement'!$C$2,Forecast!O24,Forecast!O37,Forecast!O48) -> 580508.93 | P12: =+CHOOSE('Income Statement'!$C$2,Forecast!P24,Forecast!P37,Forecast!P48) -> 596899.51 | ... T12: =+CHOOSE('Income Statement'!$C$2,Forecast!T24,Forecast!T37,Forecast!T48) -> 662464.26
B13: 11260 | C13: Engineering | D13: Travel | E13: 87942 | F13: 85224 | G13: 82469 | H13: 81005 | I13: =+CHOOSE('Income Statement'!$C$2,Forecast!I25,Forecast!I38,Forecast!I49) -> 917606.33 | J13: =+CHOOSE('Income Statement'!$C$2,Forecast!J25,Forecast!J38,Forecast!J49) -> 891283.11 | K13: =+CHOOSE('Income Statement'!$C$2,Forecast!K25,Forecast!K38,Forecast!K49) -> 864775.84 | L13: =+CHOOSE('Income Statement'!$C$2,Forecast!L25,Forecast!L38,Forecast!L49) -> 837859.35 | M13: =+CHOOSE('Income Statement'!$C$2,Forecast!M25,Forecast!M38,Forecast!M49) -> 811183.15 | N13: =+CHOOSE('Income Statement'!$C$2,Forecast!N25,Forecast!N38,Forecast!N49) -> 784491.73 | O13: =+CHOOSE('Income Statement'!$C$2,Forecast!O25,Forecast!O38,Forecast!O49) -> 757790.29 | P13: =+CHOOSE('Income Statement'!$C$2,Forecast!P25,Forecast!P38,Forecast!P49) -> 731024.53 | ... T13: =+CHOOSE('Income Statement'!$C$2,Forecast!T25,Forecast!T38,Forecast!T49) -> 624134.35
B14: 11263 | C14: Support | D14: Software | E14: 92622 | F14: 90005 | G14: 87556 | H14: 84522 | I14: =+CHOOSE('Income Statement'!$C$2,Forecast!I26,Forecast!I39,Forecast!I50) -> 958427.46 | J14: =+CHOOSE('Income Statement'!$C$2,Forecast!J26,Forecast!J39,Forecast!J50) -> 926714.97 | K14: =+CHOOSE('Income Statement'!$C$2,Forecast!K26,Forecast!K39,Forecast!K50) -> 894856.36 | L14: =+CHOOSE('Income Statement'!$C$2,Forecast!L26,Forecast!L39,Forecast!L50) -> 863372.11 | M14: =+CHOOSE('Income Statement'!$C$2,Forecast!M26,Forecast!M39,Forecast!M50) -> 831708.51 | N14: =+CHOOSE('Income Statement'!$C$2,Forecast!N26,Forecast!N39,Forecast!N50) -> 798732.8 | O14: =+CHOOSE('Income Statement'!$C$2,Forecast!O26,Forecast!O39,Forecast!O50) -> 767797.06 | P14: =+CHOOSE('Income Statement'!$C$2,Forecast!P26,Forecast!P39,Forecast!P50) -> 736574.78 | ... T14: =+CHOOSE('Income Statement'!$C$2,Forecast!T26,Forecast!T39,Forecast!T50) -> 608251.99
B15: 11264 | C15: Support | D15: Call Center | E15: 27416 | F15: 26554 | G15: 24330 | H15: 22338 | I15: =+CHOOSE('Income Statement'!$C$2,Forecast!I27,Forecast!I40,Forecast!I51) -> 243180.72 | J15: =+CHOOSE('Income Statement'!$C$2,Forecast!J27,Forecast!J40,Forecast!J51) -> 221906.5 | K15: =+CHOOSE('Income Statement'!$C$2,Forecast!K27,Forecast!K40,Forecast!K51) -> 200523.55 | L15: =+CHOOSE('Income Statement'!$C$2,Forecast!L27,Forecast!L40,Forecast!L51) -> 180162.13 | M15: =+CHOOSE('Income Statement'!$C$2,Forecast!M27,Forecast!M40,Forecast!M51) -> 159413.77 | N15: =+CHOOSE('Income Statement'!$C$2,Forecast!N27,Forecast!N40,Forecast!N51) -> 134078.38 | O15: =+CHOOSE('Income Statement'!$C$2,Forecast!O27,Forecast!O40,Forecast!O51) -> 119757.85 | P15: =+CHOOSE('Income Statement'!$C$2,Forecast!P27,Forecast!P40,Forecast!P51) -> 96773.933 | ... T15: =+CHOOSE('Income Statement'!$C$2,Forecast!T27,Forecast!T40,Forecast!T51) -> 9663.1074
B16: 11267 | C16: HR | D16: Recruiting Events | E16: 41696 | F16: 41696 | G16: 42558 | H16: 45448 | I16: =+CHOOSE('Income Statement'!$C$2,Forecast!I28,Forecast!I41,Forecast!I52) -> 541206.28 | J16: =+CHOOSE('Income Statement'!$C$2,Forecast!J28,Forecast!J41,Forecast!J52) -> 558144.26 | K16: =+CHOOSE('Income Statement'!$C$2,Forecast!K28,Forecast!K41,Forecast!K52) -> 575057.01 | L16: =+CHOOSE('Income Statement'!$C$2,Forecast!L28,Forecast!L41,Forecast!L52) -> 590292.25 | M16: =+CHOOSE('Income Statement'!$C$2,Forecast!M28,Forecast!M41,Forecast!M52) -> 606344.81 | N16: =+CHOOSE('Income Statement'!$C$2,Forecast!N28,Forecast!N41,Forecast!N52) -> 622400.21 | O16: =+CHOOSE('Income Statement'!$C$2,Forecast!O28,Forecast!O41,Forecast!O52) -> 638458.67 | P16: =+CHOOSE('Income Statement'!$C$2,Forecast!P28,Forecast!P41,Forecast!P52) -> 654519.3 | ... T16: =+CHOOSE('Income Statement'!$C$2,Forecast!T28,Forecast!T41,Forecast!T52) -> 718768
B17: 11268 | C17: HR | D17: Meetups | E17: 60285 | F17: 61225 | G17: 68994 | H17: 72410 | I17: =+CHOOSE('Income Statement'!$C$2,Forecast!I29,Forecast!I42,Forecast!I53) -> 897455.6 | J17: =+CHOOSE('Income Statement'!$C$2,Forecast!J29,Forecast!J42,Forecast!J53) -> 944556.51 | K17: =+CHOOSE('Income Statement'!$C$2,Forecast!K29,Forecast!K42,Forecast!K53) -> 1018949 | L17: =+CHOOSE('Income Statement'!$C$2,Forecast!L29,Forecast!L42,Forecast!L53) -> 1063246 | M17: =+CHOOSE('Income Statement'!$C$2,Forecast!M29,Forecast!M42,Forecast!M53) -> 1134292.3 | N17: =+CHOOSE('Income Statement'!$C$2,Forecast!N29,Forecast!N42,Forecast!N53) -> 1179362.5 | O17: =+CHOOSE('Income Statement'!$C$2,Forecast!O29,Forecast!O42,Forecast!O53) -> 1250332 | P17: =+CHOOSE('Income Statement'!$C$2,Forecast!P29,Forecast!P42,Forecast!P53) -> 1299121.6 | ... T17: =+CHOOSE('Income Statement'!$C$2,Forecast!T29,Forecast!T42,Forecast!T53) -> 1533704.8
B20: 1. Best Case | E20: Actuals | I20: Forecast
A21: x | B21: Account # | C21: Department | D21: Description | E21: ='Actual Expenses'!$C$2 -> 45536 | F21: =+EDATE(E$21,1) -> 45566 | G21: =+EDATE(F$21,1) -> 45597 | H21: =+EDATE(G$21,1) -> 45627 | I21: =+EDATE(H$21,1) -> 45658 | J21: =+EDATE(I$21,1) -> 45689 | K21: =+EDATE(J$21,1) -> 45717 | L21: =+EDATE(K$21,1) -> 45748 | M21: =+EDATE(L$21,1) -> 45778 | ... T21: =+EDATE(S$21,1) -> 45992
B22: 11256 | C22: Marketing | D22: Paid Ads | E22: 22992 | F22: 24001 | G22: 26558 | H22: 25446 | I22: =+I35*9*(1+$E$2) -> 314259.21 | J22: =+J35*9*(1+$E$2) -> 314994.34 | K22: =+K35*9*(1+$E$2) -> 334154.57 | L22: =+L35*9*(1+$E$2) -> 333466.75 | M22: =+M35*9*(1+$E$2) -> 352185.76 | N22: =+N35*9*(1+$E$2) -> 352307.11 | O22: =+O35*9*(1+$E$2) -> 370564.62 | P22: =+P35*9*(1+$E$2) -> 370696.23 | ... T22: =+T35*9*(1+$E$2) -> 407357.38
B23: 11257 | C23: Marketing | D23: Infuencers | E23: 53326 | F23: 54223 | G23: 51000 | H23: 50000 | I23: =+I36*9*(1+$E$2) -> 571644.96 | J23: =+J36*9*(1+$E$2) -> 556755.81 | K23: =+K36*9*(1+$E$2) -> 536375.04 | L23: =+L36*9*(1+$E$2) -> 521719.27 | M23: =+M36*9*(1+$E$2) -> 501598.36 | N23: =+N36*9*(1+$E$2) -> 487416.09 | O23: =+O36*9*(1+$E$2) -> 464504.02 | P23: =+P36*9*(1+$E$2) -> 450769.14 | ... T23: =+T36*9*(1+$E$2) -> 378135.41
B24: 11259 | C24: Engineering | D24: Consulting | E24: 35888 | F24: 36880 | G24: 37995 | H24: 40000 | I24: =+I37*9*(1+$E$2) -> 481852.46 | J24: =+J37*9*(1+$E$2) -> 498579.96 | K24: =+K37*9*(1+$E$2) -> 515223.16 | L24: =+L37*9*(1+$E$2) -> 531342.77 | M24: =+M37*9*(1+$E$2) -> 547730.44 | N24: =+N37*9*(1+$E$2) -> 564119.14 | O24: =+O37*9*(1+$E$2) -> 580508.93 | P24: =+P37*9*(1+$E$2) -> 596899.51 | ... T24: =+T37*9*(1+$E$2) -> 662464.26
B25: 11260 | C25: Engineering | D25: Travel | E25: 87942 | F25: 85224 | G25: 82469 | H25: 81005 | I25: =+I38*9*(1+$E$2) -> 917606.33 | J25: =+J38*9*(1+$E$2) -> 891283.11 | K25: =+K38*9*(1+$E$2) -> 864775.84 | L25: =+L38*9*(1+$E$2) -> 837859.35 | M25: =+M38*9*(1+$E$2) -> 811183.15 | N25: =+N38*9*(1+$E$2) -> 784491.73 | O25: =+O38*9*(1+$E$2) -> 757790.29 | P25: =+P38*9*(1+$E$2) -> 731024.53 | ... T25: =+T38*9*(1+$E$2) -> 624134.35
B26: 11263 | C26: Support | D26: Software | E26: 92622 | F26: 90005 | G26: 87556 | H26: 84522 | I26: =+I39*9*(1+$E$2) -> 958427.46 | J26: =+J39*9*(1+$E$2) -> 926714.97 | K26: =+K39*9*(1+$E$2) -> 894856.36 | L26: =+L39*9*(1+$E$2) -> 863372.11 | M26: =+M39*9*(1+$E$2) -> 831708.51 | N26: =+N39*9*(1+$E$2) -> 798732.8 | O26: =+O39*9*(1+$E$2) -> 767797.06 | P26: =+P39*9*(1+$E$2) -> 736574.78 | ... T26: =+T39*9*(1+$E$2) -> 608251.99
B27: 11264 | C27: Support | D27: Call Center | E27: 27416 | F27: 26554 | G27: 24330 | H27: 22338 | I27: =+I40*9*(1+$E$2) -> 243180.72 | J27: =+J40*9*(1+$E$2) -> 221906.5 | K27: =+K40*9*(1+$E$2) -> 200523.55 | L27: =+L40*9*(1+$E$2) -> 180162.13 | M27: =+M40*9*(1+$E$2) -> 159413.77 | N27: =+N40*9*(1+$E$2) -> 134078.38 | O27: =+O40*9*(1+$E$2) -> 119757.85 | P27: =+P40*9*(1+$E$2) -> 96773.933 | ... T27: =+T40*9*(1+$E$2) -> 9663.1074
B28: 11267 | C28: HR | D28: Recruiting Events | E28: 41696 | F28: 41696 | G28: 42558 | H28: 45448 | I28: =+I41*9*(1+$E$2) -> 541206.28 | J28: =+J41*9*(1+$E$2) -> 558144.26 | K28: =+K41*9*(1+$E$2) -> 575057.01 | L28: =+L41*9*(1+$E$2) -> 590292.25 | M28: =+M41*9*(1+$E$2) -> 606344.81 | N28: =+N41*9*(1+$E$2) -> 622400.21 | O28: =+O41*9*(1+$E$2) -> 638458.67 | P28: =+P41*9*(1+$E$2) -> 654519.3 | ... T28: =+T41*9*(1+$E$2) -> 718768
B29: 11268 | C29: HR | D29: Meetups | E29: 60285 | F29: 61225 | G29: 68994 | H29: 72410 | I29: =+I42*9*(1+$E$2) -> 897455.6 | J29: =+J42*9*(1+$E$2) -> 944556.51 | K29: =+K42*9*(1+$E$2) -> 1018949 | L29: =+L42*9*(1+$E$2) -> 1063246 | M29: =+M42*9*(1+$E$2) -> 1134292.3 | N29: =+N42*9*(1+$E$2) -> 1179362.5 | O29: =+O42*9*(1+$E$2) -> 1250332 | P29: =+P42*9*(1+$E$2) -> 1299121.6 | ... T29: =+T42*9*(1+$E$2) -> 1533704.8
B33: 2. Base Case | E33: Actuals | I33: Forecast
A34: x | B34: Account # | C34: Department | D34: Description | E34: ='Actual Expenses'!$C$2 -> 45536 | F34: =+EDATE(E$21,1) -> 45566 | G34: =+EDATE(F$21,1) -> 45597 | H34: =+EDATE(G$21,1) -> 45627 | I34: =+EDATE(H$21,1) -> 45658 | J34: =+EDATE(I$21,1) -> 45689 | K34: =+EDATE(J$21,1) -> 45717 | L34: =+EDATE(K$21,1) -> 45748 | M34: =+EDATE(L$21,1) -> 45778 | ... T34: =+EDATE(S$21,1) -> 45992
B35: 11256 | C35: Marketing | D35: Paid Ads | E35: 22992 | F35: 24001 | G35: 26558 | H35: 25446 | I35: =+_xlfn.FORECAST.ETS(I$34,$E35:H35,$E$34:H$34) -> 26859.761 | J35: =+_xlfn.FORECAST.ETS(J$34,$E35:I35,$E$34:I$34) -> 26922.594 | K35: =+_xlfn.FORECAST.ETS(K$34,$E35:J35,$E$34:J$34) -> 28560.22 | L35: =+_xlfn.FORECAST.ETS(L$34,$E35:K35,$E$34:K$34) -> 28501.432 | M35: =+_xlfn.FORECAST.ETS(M$34,$E35:L35,$E$34:L$34) -> 30101.347 | N35: =+_xlfn.FORECAST.ETS(N$34,$E35:M35,$E$34:M$34) -> 30111.719 | O35: =+_xlfn.FORECAST.ETS(O$34,$E35:N35,$E$34:N$34) -> 31672.189 | P35: =+_xlfn.FORECAST.ETS(P$34,$E35:O35,$E$34:O$34) -> 31683.439 | ... T35: =+_xlfn.FORECAST.ETS(T$34,$E35:S35,$E$34:S$34) -> 34816.87
B36: 11257 | C36: Marketing | D36: Infuencers | E36: 53326 | F36: 54223 | G36: 51000 | H36: 50000 | I36: =+_xlfn.FORECAST.ETS(I$34,$E36:H36,$E$34:H$34) -> 48858.544 | J36: =+_xlfn.FORECAST.ETS(J$34,$E36:I36,$E$34:I$34) -> 47585.966 | K36: =+_xlfn.FORECAST.ETS(K$34,$E36:J36,$E$34:J$34) -> 45844.021 | L36: =+_xlfn.FORECAST.ETS(L$34,$E36:K36,$E$34:K$34) -> 44591.391 | M36: =+_xlfn.FORECAST.ETS(M$34,$E36:L36,$E$34:L$34) -> 42871.655 | N36: =+_xlfn.FORECAST.ETS(N$34,$E36:M36,$E$34:M$34) -> 41659.495 | O36: =+_xlfn.FORECAST.ETS(O$34,$E36:N36,$E$34:N$34) -> 39701.198 | P36: =+_xlfn.FORECAST.ETS(P$34,$E36:O36,$E$34:O$34) -> 38527.277 | ... T36: =+_xlfn.FORECAST.ETS(T$34,$E36:S36,$E$34:S$34) -> 32319.266
B37: 11259 | C37: Engineering | D37: Consulting | E37: 35888 | F37: 36880 | G37: 37995 | H37: 40000 | I37: =+_xlfn.FORECAST.ETS(I$34,$E37:H37,$E$34:H$34) -> 41183.971 | J37: =+_xlfn.FORECAST.ETS(J$34,$E37:I37,$E$34:I$34) -> 42613.672 | K37: =+_xlfn.FORECAST.ETS(K$34,$E37:J37,$E$34:J$34) -> 44036.168 | L37: =+_xlfn.FORECAST.ETS(L$34,$E37:K37,$E$34:K$34) -> 45413.912 | M37: =+_xlfn.FORECAST.ETS(M$34,$E37:L37,$E$34:L$34) -> 46814.567 | N37: =+_xlfn.FORECAST.ETS(N$34,$E37:M37,$E$34:M$34) -> 48215.311 | O37: =+_xlfn.FORECAST.ETS(O$34,$E37:N37,$E$34:N$34) -> 49616.148 | P37: =+_xlfn.FORECAST.ETS(P$34,$E37:O37,$E$34:O$34) -> 51017.052 | ... T37: =+_xlfn.FORECAST.ETS(T$34,$E37:S37,$E$34:S$34) -> 56620.877
B38: 11260 | C38: Engineering | D38: Travel | E38: 87942 | F38: 85224 | G38: 82469 | H38: 81005 | I38: =+_xlfn.FORECAST.ETS(I$34,$E38:H38,$E$34:H$34) -> 78427.892 | J38: =+_xlfn.FORECAST.ETS(J$34,$E38:I38,$E$34:I$34) -> 76178.043 | K38: =+_xlfn.FORECAST.ETS(K$34,$E38:J38,$E$34:J$34) -> 73912.465 | L38: =+_xlfn.FORECAST.ETS(L$34,$E38:K38,$E$34:K$34) -> 71611.91 | M38: =+_xlfn.FORECAST.ETS(M$34,$E38:L38,$E$34:L$34) -> 69331.893 | N38: =+_xlfn.FORECAST.ETS(N$34,$E38:M38,$E$34:M$34) -> 67050.575 | O38: =+_xlfn.FORECAST.ETS(O$34,$E38:N38,$E$34:N$34) -> 64768.401 | P38: =+_xlfn.FORECAST.ETS(P$34,$E38:O38,$E$34:O$34) -> 62480.729 | ... T38: =+_xlfn.FORECAST.ETS(T$34,$E38:S38,$E$34:S$34) -> 53344.816
B39: 11263 | C39: Support | D39: Software | E39: 92622 | F39: 90005 | G39: 87556 | H39: 84522 | I39: =+_xlfn.FORECAST.ETS(I$34,$E39:H39,$E$34:H$34) -> 81916.877 | J39: =+_xlfn.FORECAST.ETS(J$34,$E39:I39,$E$34:I$34) -> 79206.408 | K39: =+_xlfn.FORECAST.ETS(K$34,$E39:J39,$E$34:J$34) -> 76483.45 | L39: =+_xlfn.FORECAST.ETS(L$34,$E39:K39,$E$34:K$34) -> 73792.488 | M39: =+_xlfn.FORECAST.ETS(M$34,$E39:L39,$E$34:L$34) -> 71086.198 | N39: =+_xlfn.FORECAST.ETS(N$34,$E39:M39,$E$34:M$34) -> 68267.761 | O39: =+_xlfn.FORECAST.ETS(O$34,$E39:N39,$E$34:N$34) -> 65623.68 | P39: =+_xlfn.FORECAST.ETS(P$34,$E39:O39,$E$34:O$34) -> 62955.109 | ... T39: =+_xlfn.FORECAST.ETS(T$34,$E39:S39,$E$34:S$34) -> 51987.35
B40: 11264 | C40: Support | D40: Call Center | E40: 27416 | F40: 26554 | G40: 24330 | H40: 22338 | I40: =+_xlfn.FORECAST.ETS(I$34,$E40:H40,$E$34:H$34) -> 20784.677 | J40: =+_xlfn.FORECAST.ETS(J$34,$E40:I40,$E$34:I$34) -> 18966.367 | K40: =+_xlfn.FORECAST.ETS(K$34,$E40:J40,$E$34:J$34) -> 17138.765 | L40: =+_xlfn.FORECAST.ETS(L$34,$E40:K40,$E$34:K$34) -> 15398.473 | M40: =+_xlfn.FORECAST.ETS(M$34,$E40:L40,$E$34:L$34) -> 13625.108 | N40: =+_xlfn.FORECAST.ETS(N$34,$E40:M40,$E$34:M$34) -> 11459.691 | O40: =+_xlfn.FORECAST.ETS(O$34,$E40:N40,$E$34:N$34) -> 10235.714 | P40: =+_xlfn.FORECAST.ETS(P$34,$E40:O40,$E$34:O$34) -> 8271.2763 | ... T40: =+_xlfn.FORECAST.ETS(T$34,$E40:S40,$E$34:S$34) -> 825.90662
B41: 11267 | C41: HR | D41: Recruiting Events | E41: 41696 | F41: 41696 | G41: 42558 | H41: 45448 | I41: =+_xlfn.FORECAST.ETS(I$34,$E41:H41,$E$34:H$34) -> 46256.947 | J41: =+_xlfn.FORECAST.ETS(J$34,$E41:I41,$E$34:I$34) -> 47704.638 | K41: =+_xlfn.FORECAST.ETS(K$34,$E41:J41,$E$34:J$34) -> 49150.171 | L41: =+_xlfn.FORECAST.ETS(L$34,$E41:K41,$E$34:K$34) -> 50452.329 | M41: =+_xlfn.FORECAST.ETS(M$34,$E41:L41,$E$34:L$34) -> 51824.343 | N41: =+_xlfn.FORECAST.ETS(N$34,$E41:M41,$E$34:M$34) -> 53196.599 | O41: =+_xlfn.FORECAST.ETS(O$34,$E41:N41,$E$34:N$34) -> 54569.117 | P41: =+_xlfn.FORECAST.ETS(P$34,$E41:O41,$E$34:O$34) -> 55941.82 | ... T41: =+_xlfn.FORECAST.ETS(T$34,$E41:S41,$E$34:S$34) -> 61433.162
B42: 11268 | C42: HR | D42: Meetups | E42: 60285 | F42: 61225 | G42: 68994 | H42: 72410 | I42: =+_xlfn.FORECAST.ETS(I$34,$E42:H42,$E$34:H$34) -> 76705.607 | J42: =+_xlfn.FORECAST.ETS(J$34,$E42:I42,$E$34:I$34) -> 80731.326 | K42: =+_xlfn.FORECAST.ETS(K$34,$E42:J42,$E$34:J$34) -> 87089.658 | L42: =+_xlfn.FORECAST.ETS(L$34,$E42:K42,$E$34:K$34) -> 90875.73 | M42: =+_xlfn.FORECAST.ETS(M$34,$E42:L42,$E$34:L$34) -> 96948.062 | N42: =+_xlfn.FORECAST.ETS(N$34,$E42:M42,$E$34:M$34) -> 100800.22 | O42: =+_xlfn.FORECAST.ETS(O$34,$E42:N42,$E$34:N$34) -> 106865.98 | P42: =+_xlfn.FORECAST.ETS(P$34,$E42:O42,$E$34:O$34) -> 111036.03 | ... T42: =+_xlfn.FORECAST.ETS(T$34,$E42:S42,$E$34:S$34) -> 131085.88
B44: 3. Worst Case | E44: Actuals | I44: Forecast
B45: Account # | C45: Department | D45: Description | E45: ='Actual Expenses'!$C$2 -> 45536 | F45: =+EDATE(E$21,1) -> 45566 | G45: =+EDATE(F$21,1) -> 45597 | H45: =+EDATE(G$21,1) -> 45627 | I45: =+EDATE(H$21,1) -> 45658 | J45: =+EDATE(I$21,1) -> 45689 | K45: =+EDATE(J$21,1) -> 45717 | L45: =+EDATE(K$21,1) -> 45748 | M45: =+EDATE(L$21,1) -> 45778 | ... T45: =+EDATE(S$21,1) -> 45992
B46: 11256 | C46: Marketing | D46: Paid Ads | E46: 22992 | F46: 24001 | G46: 26558 | H46: 25446 | I46: =+I35*(1-$E$3) -> 18801.833 | J46: =+J35*(1-$E$3) -> 18845.815 | K46: =+K35*(1-$E$3) -> 19992.154 | L46: =+L35*(1-$E$3) -> 19951.002 | M46: =+M35*(1-$E$3) -> 21070.943 | N46: =+N35*(1-$E$3) -> 21078.203 | O46: =+O35*(1-$E$3) -> 22170.533 | P46: =+P35*(1-$E$3) -> 22178.407 | ... T46: =+T35*(1-$E$3) -> 24371.809
B47: 11257 | C47: Marketing | D47: Infuencers | E47: 53326 | F47: 54223 | G47: 51000 | H47: 50000 | I47: =+I36*(1-$E$3) -> 34200.981 | J47: =+J36*(1-$E$3) -> 33310.176 | K47: =+K36*(1-$E$3) -> 32090.815 | L47: =+L36*(1-$E$3) -> 31213.974 | M47: =+M36*(1-$E$3) -> 30010.158 | N47: =+N36*(1-$E$3) -> 29161.646 | O47: =+O36*(1-$E$3) -> 27790.839 | P47: =+P36*(1-$E$3) -> 26969.094 | ... T47: =+T36*(1-$E$3) -> 22623.486
B48: 11259 | C48: Engineering | D48: Consulting | E48: 35888 | F48: 36880 | G48: 37995 | H48: 40000 | I48: =+I37*(1-$E$3) -> 28828.78 | J48: =+J37*(1-$E$3) -> 29829.57 | K48: =+K37*(1-$E$3) -> 30825.318 | L48: =+L37*(1-$E$3) -> 31789.738 | M48: =+M37*(1-$E$3) -> 32770.197 | N48: =+N37*(1-$E$3) -> 33750.718 | O48: =+O37*(1-$E$3) -> 34731.303 | P48: =+P37*(1-$E$3) -> 35711.936 | ... T48: =+T37*(1-$E$3) -> 39634.614
B49: 11260 | C49: Engineering | D49: Travel | E49: 87942 | F49: 85224 | G49: 82469 | H49: 81005 | I49: =+I38*(1-$E$3) -> 54899.524 | J49: =+J38*(1-$E$3) -> 53324.63 | K49: =+K38*(1-$E$3) -> 51738.726 | L49: =+L38*(1-$E$3) -> 50128.337 | M49: =+M38*(1-$E$3) -> 48532.325 | N49: =+N38*(1-$E$3) -> 46935.402 | O49: =+O38*(1-$E$3) -> 45337.88 | P49: =+P38*(1-$E$3) -> 43736.51 | ... T49: =+T38*(1-$E$3) -> 37341.371
B50: 11263 | C50: Support | D50: Software | E50: 92622 | F50: 90005 | G50: 87556 | H50: 84522 | I50: =+I39*(1-$E$3) -> 57341.814 | J50: =+J39*(1-$E$3) -> 55444.485 | K50: =+K39*(1-$E$3) -> 53538.415 | L50: =+L39*(1-$E$3) -> 51654.742 | M50: =+M39*(1-$E$3) -> 49760.338 | N50: =+N39*(1-$E$3) -> 47787.432 | O50: =+O39*(1-$E$3) -> 45936.576 | P50: =+P39*(1-$E$3) -> 44068.577 | ... T50: =+T39*(1-$E$3) -> 36391.145
B51: 11264 | C51: Support | D51: Call Center | E51: 27416 | F51: 26554 | G51: 24330 | H51: 22338 | I51: =+I40*(1-$E$3) -> 14549.274 | J51: =+J40*(1-$E$3) -> 13276.457 | K51: =+K40*(1-$E$3) -> 11997.136 | L51: =+L40*(1-$E$3) -> 10778.931 | M51: =+M40*(1-$E$3) -> 9537.5757 | N51: =+N40*(1-$E$3) -> 8021.7835 | O51: =+O40*(1-$E$3) -> 7164.9997 | P51: =+P40*(1-$E$3) -> 5789.8934 | ... T51: =+T40*(1-$E$3) -> 578.13463
...

Sheet Income Statement
B2: Operating Expenses Scenario | C2: 1
A4: x | B4: Income Statement Forecast
B5: in USD | C5: 45658 | D5: =+EDATE(C5,1) -> 45689 | E5: =+EDATE(D5,1) -> 45717 | F5: =+EDATE(E5,1) -> 45748 | G5: =+EDATE(F5,1) -> 45778 | H5: =+EDATE(G5,1) -> 45809 | I5: =+EDATE(H5,1) -> 45839 | J5: =+EDATE(I5,1) -> 45870 | K5: =+EDATE(J5,1) -> 45901 | ... N5: =+EDATE(M5,1) -> 45992
B6: Revenue | C6: =+C31 -> 8268438.9 | D6: =+D31 -> 8136334.7 | E6: =+E31 -> 8124943.1 | F6: =+F31 -> 7981736.3 | G6: =+G31 -> 7968651.8 | H6: =+H31 -> 9019249.2 | I6: =+I31 -> 8969255.7 | J6: =+J31 -> 8823146.7 | ... N6: =+N31 -> 8436774.4
B7: COGS | C7: =+C35 -> 2976638 | D7: =+D35 -> 2929080.5 | E7: =+E35 -> 2924979.5 | F7: =+F35 -> 2873425.1 | G7: =+G35 -> 2868714.6 | H7: =+H35 -> 3246929.7 | I7: =+I35 -> 3228932.1 | J7: =+J35 -> 3176332.8 | ... N7: =+N35 -> 3037238.8
B8: Gross Profit | C8: =+C6-C7 -> 5291800.9 | D8: =+D6-D7 -> 5207254.2 | E8: =+E6-E7 -> 5199963.6 | F8: =+F6-F7 -> 5108311.2 | G8: =+G6-G7 -> 5099937.1 | H8: =+H6-H7 -> 5772319.5 | I8: =+I6-I7 -> 5740323.7 | J8: =+J6-J7 -> 5646813.9 | ... N8: =+N6-N7 -> 5399535.6
B10: Operating expenses:
B11: {=+_xlfn.UNIQUE(Forecast!C35:C42)} -> Marketing | C11: =+SUMIFS(Forecast!I$10:I$17,Forecast!$C$10:$C$17,'Income Statement'!$B11) -> 885904.17 | D11: =+SUMIFS(Forecast!J$10:J$17,Forecast!$C$10:$C$17,'Income Statement'!$B11) -> 871750.15 | E11: =+SUMIFS(Forecast!K$10:K$17,Forecast!$C$10:$C$17,'Income Statement'!$B11) -> 870529.62 | F11: =+SUMIFS(Forecast!L$10:L$17,Forecast!$C$10:$C$17,'Income Statement'!$B11) -> 855186.03 | G11: =+SUMIFS(Forecast!M$10:M$17,Forecast!$C$10:$C$17,'Income Statement'!$B11) -> 853784.12 | H11: =+SUMIFS(Forecast!N$10:N$17,Forecast!$C$10:$C$17,'Income Statement'!$B11) -> 839723.2 | I11: =+SUMIFS(Forecast!O$10:O$17,Forecast!$C$10:$C$17,'Income Statement'!$B11) -> 835068.64 | J11: =+SUMIFS(Forecast!P$10:P$17,Forecast!$C$10:$C$17,'Income Statement'!$B11) -> 821465.38 | ... N11: =+SUMIFS(Forecast!T$10:T$17,Forecast!$C$10:$C$17,'Income Statement'!$B11) -> 785492.79
B12: Engineering | C12: =+SUMIFS(Forecast!I$10:I$17,Forecast!$C$10:$C$17,'Income Statement'!$B12) -> 1399458.8 | D12: =+SUMIFS(Forecast!J$10:J$17,Forecast!$C$10:$C$17,'Income Statement'!$B12) -> 1389863.1 | E12: =+SUMIFS(Forecast!K$10:K$17,Forecast!$C$10:$C$17,'Income Statement'!$B12) -> 1379999 | F12: =+SUMIFS(Forecast!L$10:L$17,Forecast!$C$10:$C$17,'Income Statement'!$B12) -> 1369202.1 | G12: =+SUMIFS(Forecast!M$10:M$17,Forecast!$C$10:$C$17,'Income Statement'!$B12) -> 1358913.6 | H12: =+SUMIFS(Forecast!N$10:N$17,Forecast!$C$10:$C$17,'Income Statement'!$B12) -> 1348610.9 | I12: =+SUMIFS(Forecast!O$10:O$17,Forecast!$C$10:$C$17,'Income Statement'!$B12) -> 1338299.2 | J12: =+SUMIFS(Forecast!P$10:P$17,Forecast!$C$10:$C$17,'Income Statement'!$B12) -> 1327924 | ... N12: =+SUMIFS(Forecast!T$10:T$17,Forecast!$C$10:$C$17,'Income Statement'!$B12) -> 1286598.6
B13: Support | C13: =+SUMIFS(Forecast!I$10:I$17,Forecast!$C$10:$C$17,'Income Statement'!$B13) -> 1201608.2 | D13: =+SUMIFS(Forecast!J$10:J$17,Forecast!$C$10:$C$17,'Income Statement'!$B13) -> 1148621.5 | E13: =+SUMIFS(Forecast!K$10:K$17,Forecast!$C$10:$C$17,'Income Statement'!$B13) -> 1095379.9 | F13: =+SUMIFS(Forecast!L$10:L$17,Forecast!$C$10:$C$17,'Income Statement'!$B13) -> 1043534.2 | G13: =+SUMIFS(Forecast!M$10:M$17,Forecast!$C$10:$C$17,'Income Statement'!$B13) -> 991122.28 | H13: =+SUMIFS(Forecast!N$10:N$17,Forecast!$C$10:$C$17,'Income Statement'!$B13) -> 932811.18 | I13: =+SUMIFS(Forecast!O$10:O$17,Forecast!$C$10:$C$17,'Income Statement'!$B13) -> 887554.91 | J13: =+SUMIFS(Forecast!P$10:P$17,Forecast!$C$10:$C$17,'Income Statement'!$B13) -> 833348.71 | ... N13: =+SUMIFS(Forecast!T$10:T$17,Forecast!$C$10:$C$17,'Income Statement'!$B13) -> 617915.1
B14: HR | C14: =+SUMIFS(Forecast!I$10:I$17,Forecast!$C$10:$C$17,'Income Statement'!$B14) -> 1438661.9 | D14: =+SUMIFS(Forecast!J$10:J$17,Forecast!$C$10:$C$17,'Income Statement'!$B14) -> 1502700.8 | E14: =+SUMIFS(Forecast!K$10:K$17,Forecast!$C$10:$C$17,'Income Statement'!$B14) -> 1594006 | F14: =+SUMIFS(Forecast!L$10:L$17,Forecast!$C$10:$C$17,'Income Statement'!$B14) -> 1653538.3 | G14: =+SUMIFS(Forecast!M$10:M$17,Forecast!$C$10:$C$17,'Income Statement'!$B14) -> 1740637.1 | H14: =+SUMIFS(Forecast!N$10:N$17,Forecast!$C$10:$C$17,'Income Statement'!$B14) -> 1801762.8 | I14: =+SUMIFS(Forecast!O$10:O$17,Forecast!$C$10:$C$17,'Income Statement'!$B14) -> 1888790.7 | J14: =+SUMIFS(Forecast!P$10:P$17,Forecast!$C$10:$C$17,'Income Statement'!$B14) -> 1953640.9 | ... N14: =+SUMIFS(Forecast!T$10:T$17,Forecast!$C$10:$C$17,'Income Statement'!$B14) -> 2252472.8
B15: Total operating expenses | C15: =SUM(C11:C14) -> 4925633 | D15: =SUM(D11:D14) -> 4912935.5 | E15: =SUM(E11:E14) -> 4939914.5 | F15: =SUM(F11:F14) -> 4921460.7 | G15: =SUM(G11:G14) -> 4944457.1 | H15: =SUM(H11:H14) -> 4922908 | I15: =SUM(I11:I14) -> 4949713.4 | J15: =SUM(J11:J14) -> 4936379 | ... N15: =SUM(N11:N14) -> 4942479.3
B16: Operating income | C16: =+C8-C15 -> 366167.88 | D16: =+D8-D15 -> 294318.77 | E16: =+E8-E15 -> 260049.03 | F16: =+F8-F15 -> 186850.53 | G16: =+G8-G15 -> 155480.01 | H16: =+H8-H15 -> 849411.48 | I16: =+I8-I15 -> 790610.25 | J16: =+J8-J15 -> 710434.85 | ... N16: =+N8-N15 -> 457056.36
B18: Other income / (expense), net | C18: =+C38 -> 68462.674 | D18: =+D38 -> 67368.852 | E18: =+E38 -> 67274.529 | F18: =+F38 -> 66088.776 | G18: =+G38 -> 65980.437 | H18: =+H38 -> 74679.383 | I18: =+I38 -> 74265.438 | J18: =+J38 -> 73055.654 | ... N18: =+N38 -> 69856.492
B19: Pre-tax income | C19: =+C16-C18 -> 297705.2 | D19: =+D16-D18 -> 226949.92 | E19: =+E16-E18 -> 192774.5 | F19: =+F16-F18 -> 120761.75 | G19: =+G16-G18 -> 89499.571 | H19: =+H16-H18 -> 774732.1 | I19: =+I16-I18 -> 716344.82 | J19: =+J16-J18 -> 637379.2 | ... N19: =+N16-N18 -> 387199.87
B21: Taxes | C21: =IF(C19>0,C19*$C$40,0) -> 59541.04 | D21: =IF(D19>0,D19*$C$40,0) -> 45389.984 | E21: =IF(E19>0,E19*$C$40,0) -> 38554.901 | F21: =IF(F19>0,F19*$C$40,0) -> 24152.35 | G21: =IF(G19>0,G19*$C$40,0) -> 17899.914 | H21: =IF(H19>0,H19*$C$40,0) -> 154946.42 | I21: =IF(I19>0,I19*$C$40,0) -> 143268.96 | J21: =IF(J19>0,J19*$C$40,0) -> 127475.84 | ... N21: =IF(N19>0,N19*$C$40,0) -> 77439.973
B22: Net Income | C22: =+C19-C21 -> 238164.16 | D22: =+D19-D21 -> 181559.94 | E22: =+E19-E21 -> 154219.6 | F22: =+F19-F21 -> 96609.399 | G22: =+G19-G21 -> 71599.657 | H22: =+H19-H21 -> 619785.68 | I22: =+I19-I21 -> 573075.85 | J22: =+J19-J21 -> 509903.36 | ... N22: =+N19-N21 -> 309759.89
A25: x | B25: Assumptions
B26: Revenue
B27: Customer Acquisition Cost | C27: 30 | D27: 30 | E27: 30 | F27: 30 | G27: 30 | H27: 27 | I27: 27 | J27: 27 | K27: 27 | L27: 27 | M27: 27 | N27: 27
B28: Price | C28: 280 | D28: 280 | E28: 280 | F28: 280 | G28: 280 | H28: 290 | I28: 290 | J28: 290 | K28: 290 | L28: 290 | M28: 290 | N28: 290
B30: Units Sold | C30: =+C11/C27 -> 29530.139 | D30: =+D11/D27 -> 29058.338 | E30: =+E11/E27 -> 29017.654 | F30: =+F11/F27 -> 28506.201 | G30: =+G11/G27 -> 28459.471 | H30: =+H11/H27 -> 31100.859 | I30: =+I11/I27 -> 30928.468 | J30: =+J11/J27 -> 30424.644 | ... N30: =+N11/N27 -> 29092.326
B31: Revenue | C31: =+C30*C28 -> 8268438.9 | D31: =+D30*D28 -> 8136334.7 | E31: =+E30*E28 -> 8124943.1 | F31: =+F30*F28 -> 7981736.3 | G31: =+G30*G28 -> 7968651.8 | H31: =+H30*H28 -> 9019249.2 | I31: =+I30*I28 -> 8969255.7 | J31: =+J30*J28 -> 8823146.7 | ... N31: =+N30*N28 -> 8436774.4
B33: Other
B34: COGS % of Revenue | C34: 0.36 | D34: 0.36 | E34: 0.36 | F34: 0.36 | G34: 0.36 | H34: 0.36 | I34: 0.36 | J34: 0.36 | K34: 0.36 | L34: 0.36 | M34: 0.36 | N34: 0.36
B35: COGS | C35: =C34*C31 -> 2976638 | D35: =D34*D31 -> 2929080.5 | E35: =E34*E31 -> 2924979.5 | F35: =F34*F31 -> 2873425.1 | G35: =G34*G31 -> 2868714.6 | H35: =H34*H31 -> 3246929.7 | I35: =I34*I31 -> 3228932.1 | J35: =J34*J31 -> 3176332.8 | ... N35: =N34*N31 -> 3037238.8
B37: Other income / (expense), net % of COGS | C37: 0.023 | D37: 0.023 | E37: 0.023 | F37: 0.023 | G37: 0.023 | H37: 0.023 | I37: 0.023 | J37: 0.023 | K37: 0.023 | L37: 0.023 | M37: 0.023 | N37: 0.023
B38: Other income / (expense), net | C38: =C35*C37 -> 68462.674 | D38: =D35*D37 -> 67368.852 | E38: =E35*E37 -> 67274.529 | F38: =F35*F37 -> 66088.776 | G38: =G35*G37 -> 65980.437 | H38: =H35*H37 -> 74679.383 | I38: =I35*I37 -> 74265.438 | J38: =J35*J37 -> 73055.654 | ... N38: =N35*N37 -> 69856.492
A40: x | B40: Tax Rate | C40: 0.2

Sheet Visuals
B2: in USD | C2: ='Income Statement'!C5 -> 45658 | D2: =EDATE(C2,1) -> 45689 | E2: =EDATE(D2,1) -> 45717 | F2: =EDATE(E2,1) -> 45748 | G2: =EDATE(F2,1) -> 45778 | H2: =EDATE(G2,1) -> 45809 | I2: =EDATE(H2,1) -> 45839 | J2: =EDATE(I2,1) -> 45870 | K2: =EDATE(J2,1) -> 45901 | ... N2: =EDATE(M2,1) -> 45992
B3: Revenue | C3: ='Income Statement'!C6 -> 8268438.9 | D3: ='Income Statement'!D6 -> 8136334.7 | E3: ='Income Statement'!E6 -> 8124943.1 | F3: ='Income Statement'!F6 -> 7981736.3 | G3: ='Income Statement'!G6 -> 7968651.8 | H3: ='Income Statement'!H6 -> 9019249.2 | I3: ='Income Statement'!I6 -> 8969255.7 | J3: ='Income Statement'!J6 -> 8823146.7 | ... N3: ='Income Statement'!N6 -> 8436774.4
B4: Profit Margin | C4: ='Income Statement'!C22/Visuals!C3 -> 0.028804006 | D4: ='Income Statement'!D22/Visuals!D3 -> 0.022314708 | E4: ='Income Statement'!E22/Visuals!E3 -> 0.018981007 | F4: ='Income Statement'!F22/Visuals!F3 -> 0.012103807 | G4: ='Income Statement'!G22/Visuals!G3 -> 0.0089851658 | H4: ='Income Statement'!H22/Visuals!H3 -> 0.068718101 | I4: ='Income Statement'!I22/Visuals!I3 -> 0.063893356 | J4: ='Income Statement'!J22/Visuals!J3 -> 0.057791554 | ... N4: ='Income Statement'!N22/Visuals!N3 -> 0.036715441
